<?xml version="1.0" encoding="utf-8"?>
<!-- This URDF was automatically created by SolidWorks to URDF Exporter! Originally created by Stephen Brawner (brawner@gmail.com) 
     Commit Version: 1.6.0-4-g7f85cfe  Build Version: 1.6.7995.38578
     For more information, please see http://wiki.ros.org/sw_urdf_exporter -->
<robot
  name="manipulator">
  <link
    name="base_link">
    <inertial>
      <origin
        xyz="-0.00060264 0.00060262 0.0092865"
        rpy="0 0 0" />
      <mass
        value="0.3076" />
      <inertia
        ixx="0.00039669"
        ixy="-1.7529E-05"
        ixz="1.5241E-06"
        iyy="0.00039669"
        iyz="-1.5241E-06"
        izz="0.00077358" />
    </inertial>
    <visual>
      <origin
        xyz="0 0 0"
        rpy="0 0 0" />
      <geometry>
        <mesh
          filename="package://Assem1 by lalit kumar.SLDASM/meshes/base_link.STL" />
      </geometry>
      <material
        name="">
        <color
          rgba="0.75294 0.75294 0.75294 1" />
      </material>
    </visual>
    <collision>
      <origin
        xyz="0 0 0"
        rpy="0 0 0" />
      <geometry>
        <mesh
          filename="package://Assem1 by lalit kumar.SLDASM/meshes/base_link.STL" />
      </geometry>
    </collision>
  </link>
  <link
    name="link 1">
    <inertial>
      <origin
        xyz="-0.085809 -0.0083647 7.1502E-06"
        rpy="0 0 0" />
      <mass
        value="1.3763" />
      <inertia
        ixx="0.002624"
        ixy="-0.00031934"
        ixz="1.6345E-07"
        iyy="0.0022407"
        iyz="4.4454E-07"
        izz="0.0024148" />
    </inertial>
    <visual>
      <origin
        xyz="0 0 0"
        rpy="0 0 0" />
      <geometry>
        <mesh
          filename="package://Assem1 by lalit kumar.SLDASM/meshes/link 1.STL" />
      </geometry>
      <material
        name="">
        <color
          rgba="0.75294 0.75294 0.75294 1" />
      </material>
    </visual>
    <collision>
      <origin
        xyz="0 0 0"
        rpy="0 0 0" />
      <geometry>
        <mesh
          filename="package://Assem1 by lalit kumar.SLDASM/meshes/link 1.STL" />
      </geometry>
    </collision>
  </link>
  <joint
    name="joint_1"
    type="revolute">
    <origin
      xyz="0 0 0.003"
      rpy="0.7854 1.5708 0" />
    <parent
      link="base_link" />
    <child
      link="link 1" />
    <axis
      xyz="1 0 0" />
    <limit
      lower="3.142"
      upper="-3.142"
      effort="0"
      velocity="0" />
  </joint>
  <link
    name="link_2">
    <inertial>
      <origin
        xyz="-0.13429 -0.2995 1.1884E-06"
        rpy="0 0 0" />
      <mass
        value="4.5805" />
      <inertia
        ixx="0.021665"
        ixy="-2.5932E-13"
        ixz="2.2571E-07"
        iyy="0.0062873"
        iyz="8.9646E-07"
        izz="0.021247" />
    </inertial>
    <visual>
      <origin
        xyz="0 0 0"
        rpy="0 0 0" />
      <geometry>
        <mesh
          filename="package://Assem1 by lalit kumar.SLDASM/meshes/link_2.STL" />
      </geometry>
      <material
        name="">
        <color
          rgba="0.75294 0.75294 0.75294 1" />
      </material>
    </visual>
    <collision>
      <origin
        xyz="0 0 0"
        rpy="0 0 0" />
      <geometry>
        <mesh
          filename="package://Assem1 by lalit kumar.SLDASM/meshes/link_2.STL" />
      </geometry>
    </collision>
  </link>
  <joint
    name="joint_2"
    type="revolute">
    <origin
      xyz="0 0 0"
      rpy="3.1416 0 1.5708" />
    <parent
      link="link 1" />
    <child
      link="link_2" />
    <axis
      xyz="1 0 0" />
    <limit
      lower="3.142"
      upper="-3.142"
      effort="0"
      velocity="0" />
  </joint>
  <link
    name="Link_3">
    <inertial>
      <origin
        xyz="-0.17537 -0.0036192 2.7677E-06"
        rpy="0 0 0" />
      <mass
        value="2.4854" />
      <inertia
        ixx="0.002054"
        ixy="0.00011286"
        ixz="-3.946E-07"
        iyy="0.011633"
        iyz="-2.729E-07"
        izz="0.011493" />
    </inertial>
    <visual>
      <origin
        xyz="0 0 0"
        rpy="0 0 0" />
      <geometry>
        <mesh
          filename="package://Assem1 by lalit kumar.SLDASM/meshes/Link_3.STL" />
      </geometry>
      <material
        name="">
        <color
          rgba="0.75294 0.75294 0.75294 1" />
      </material>
    </visual>
    <collision>
      <origin
        xyz="0 0 0"
        rpy="0 0 0" />
      <geometry>
        <mesh
          filename="package://Assem1 by lalit kumar.SLDASM/meshes/Link_3.STL" />
      </geometry>
    </collision>
  </link>
  <joint
    name="Joint_3"
    type="revolute">
    <origin
      xyz="-0.01505 -0.512 0"
      rpy="-3.1416 0 1.5708" />
    <parent
      link="link_2" />
    <child
      link="Link_3" />
    <axis
      xyz="0 1 0" />
    <limit
      lower="3.142"
      upper="-3.142"
      effort="0"
      velocity="0" />
  </joint>
  <link
    name="link_4">
    <inertial>
      <origin
        xyz="0.0047575 0.0043641 1.4561E-05"
        rpy="0 0 0" />
      <mass
        value="0.46512" />
      <inertia
        ixx="0.0003205"
        ixy="-4.2782E-05"
        ixz="-4.092E-07"
        iyy="0.00037353"
        iyz="-2.8151E-07"
        izz="0.00034914" />
    </inertial>
    <visual>
      <origin
        xyz="0 0 0"
        rpy="0 0 0" />
      <geometry>
        <mesh
          filename="package://Assem1 by lalit kumar.SLDASM/meshes/link_4.STL" />
      </geometry>
      <material
        name="">
        <color
          rgba="0.75294 0.75294 0.75294 1" />
      </material>
    </visual>
    <collision>
      <origin
        xyz="0 0 0"
        rpy="0 0 0" />
      <geometry>
        <mesh
          filename="package://Assem1 by lalit kumar.SLDASM/meshes/link_4.STL" />
      </geometry>
    </collision>
  </link>
  <joint
    name="joint_4"
    type="revolute">
    <origin
      xyz="-0.39225 -0.09492 0"
      rpy="-3.1416 0 1.5708" />
    <parent
      link="Link_3" />
    <child
      link="link_4" />
    <axis
      xyz="1 0 0" />
    <limit
      lower="3.142"
      upper="-3.142"
      effort="0"
      velocity="0" />
  </joint>
  <link
    name="link_5">
    <inertial>
      <origin
        xyz="0.0047571 0.004364 1.4488E-05"
        rpy="0 0 0" />
      <mass
        value="0.46512" />
      <inertia
        ixx="0.0003205"
        ixy="-4.2783E-05"
        ixz="-4.0947E-07"
        iyy="0.00037353"
        iyz="-2.8151E-07"
        izz="0.00034914" />
    </inertial>
    <visual>
      <origin
        xyz="0 0 0"
        rpy="0 0 0" />
      <geometry>
        <mesh
          filename="package://Assem1 by lalit kumar.SLDASM/meshes/link_5.STL" />
      </geometry>
      <material
        name="">
        <color
          rgba="0.75294 0.75294 0.75294 1" />
      </material>
    </visual>
    <collision>
      <origin
        xyz="0 0 0"
        rpy="0 0 0" />
      <geometry>
        <mesh
          filename="package://Assem1 by lalit kumar.SLDASM/meshes/link_5.STL" />
      </geometry>
    </collision>
  </link>
  <joint
    name="joint_5"
    type="revolute">
    <origin
      xyz="0 -0.09492 0"
      rpy="3.1416 0 1.5708" />
    <parent
      link="link_4" />
    <child
      link="link_5" />
    <axis
      xyz="1 0 0" />
    <limit
      lower="3.142"
      upper="-3.142"
      effort="0"
      velocity="0" />
  </joint>
  <link
    name="link_6">
    <inertial>
      <origin
        xyz="-0.083772 0.105 0.081001"
        rpy="0 0 0" />
      <mass
        value="0.13015" />
      <inertia
        ixx="5.4976E-05"
        ixy="-3.9302E-19"
        ixz="-2.4225E-19"
        iyy="9.0143E-05"
        iyz="1.0559E-07"
        izz="5.5674E-05" />
    </inertial>
    <visual>
      <origin
        xyz="0 0 0"
        rpy="0 0 0" />
      <geometry>
        <mesh
          filename="package://Assem1 by lalit kumar.SLDASM/meshes/link_6.STL" />
      </geometry>
      <material
        name="">
        <color
          rgba="0.75294 0.75294 0.75294 1" />
      </material>
    </visual>
    <collision>
      <origin
        xyz="0 0 0"
        rpy="0 0 0" />
      <geometry>
        <mesh
          filename="package://Assem1 by lalit kumar.SLDASM/meshes/link_6.STL" />
      </geometry>
    </collision>
  </link>
  <joint
    name="joint_6"
    type="revolute">
    <origin
      xyz="0.1164 -0.16865 0"
      rpy="0 -0.76746 0" />
    <parent
      link="link_5" />
    <child
      link="link_6" />
    <axis
      xyz="0 -1 0" />
    <limit
      lower="3.142"
      upper="-3.142"
      effort="0"
      velocity="0" />
  </joint>
</robot>